Workbook

Sheet 2025 Team
A1: Team | B1: ABB | C1: Pass Plays | D1: Run Plays | E1: Total Plays | F1: Pass % | G1: Run %
A2: Arizona Cardinals | B2: ARI | C2: 649 | D2: 366 | E2: =SUM(C2:D2) -> 1015 | F2: =C2/E2 -> 0.63940887 | G2: =D2/E2 -> 0.36059113
A3: Atlanta Falcons | B3: ATL | C3: 545 | D3: 477 | E3: =SUM(C3:D3) -> 1022 | F3: =C3/E3 -> 0.5332681 | G3: =D3/E3 -> 0.4667319
A4: Baltimore Ravens | B4: BAL | C4: 422 | D4: 507 | E4: =SUM(C4:D4) -> 929 | F4: =C4/E4 -> 0.45425188 | G4: =D4/E4 -> 0.54574812
A5: Buffalo Bills | B5: BUF | C5: 495 | D5: 547 | E5: =SUM(C5:D5) -> 1042 | F5: =C5/E5 -> 0.47504798 | G5: =D5/E5 -> 0.52495202
A6: Carolina Panthers | B6: CAR | C6: 515 | D6: 461 | E6: =SUM(C6:D6) -> 976 | F6: =C6/E6 -> 0.52766393 | G6: =D6/E6 -> 0.47233607
A7: Chicago Bears | B7: CHI | C7: 574 | D7: 505 | E7: =SUM(C7:D7) -> 1079 | F7: =C7/E7 -> 0.53197405 | G7: =D7/E7 -> 0.46802595
A8: Cincinnati Bengals | B8: CIN | C8: 640 | D8: 381 | E8: =SUM(C8:D8) -> 1021 | F8: =C8/E8 -> 0.62683643 | G8: =D8/E8 -> 0.37316357
A9: Cleveland Browns | B9: CLE | C9: 558 | D9: 421 | E9: =SUM(C9:D9) -> 979 | F9: =C9/E9 -> 0.56996936 | G9: =D9/E9 -> 0.43003064
A10: Dallas Cowboys | B10: DAL | C10: 624 | D10: 465 | E10: =SUM(C10:D10) -> 1089 | F10: =C10/E10 -> 0.57300275 | G10: =D10/E10 -> 0.42699725
A11: Denver Broncos | B11: DEN | C11: 613 | D11: 456 | E11: =SUM(C11:D11) -> 1069 | F11: =C11/E11 -> 0.57343312 | G11: =D11/E11 -> 0.42656688
A12: Detroit Lions | B12: DET | C12: 582 | D12: 442 | E12: =SUM(C12:D12) -> 1024 | F12: =C12/E12 -> 0.56835938 | G12: =D12/E12 -> 0.43164062
A13: Green Bay Packers | B13: GNB | C13: 489 | D13: 492 | E13: =SUM(C13:D13) -> 981 | F13: =C13/E13 -> 0.49847095 | G13: =D13/E13 -> 0.50152905
... A33: Washington Commanders | B33: WAS | C33: 469 | D33: 484 | E33: =SUM(C33:D33) -> 953 | F33: =C33/E33 -> 0.49213012 | G33: =D33/E33 -> 0.50786988

Sheet 2024 Team
A1: Team | B1: ABB | C1: Pass Plays | D1: Run Plays | E1: Total Plays | F1: Pass % | G1: Run %
A2: Detroit Lions | B2: DET | C2: 551 | D2: 534 | E2: =SUM(C2:D2) -> 1085 | F2: =C2/E2 -> 0.5078341 | G2: =D2/E2 -> 0.4921659
A3: Buffalo Bills | B3: BUF | C3: 520 | D3: 491 | E3: =SUM(C3:D3) -> 1011 | F3: =C3/E3 -> 0.51434224 | G3: =D3/E3 -> 0.48565776
A4: Baltimore Ravens | B4: BAL | C4: 477 | D4: 554 | E4: =SUM(C4:D4) -> 1031 | F4: =C4/E4 -> 0.46265761 | G4: =D4/E4 -> 0.53734239
A5: Tampa Bay Buccaneers | B5: TAM | C5: 571 | D5: 483 | E5: =SUM(C5:D5) -> 1054 | F5: =C5/E5 -> 0.54174573 | G5: =D5/E5 -> 0.45825427
A6: Washington Commanders | B6: WAS | C6: 525 | D6: 526 | E6: =SUM(C6:D6) -> 1051 | F6: =C6/E6 -> 0.49952426 | G6: =D6/E6 -> 0.50047574
A7: Cincinnati Bengals | B7: CIN | C7: 652 | D7: 380 | E7: =SUM(C7:D7) -> 1032 | F7: =C7/E7 -> 0.63178295 | G7: =D7/E7 -> 0.36821705
A8: Philadelphia Eagles | B8: PHI | C8: 448 | D8: 621 | E8: =SUM(C8:D8) -> 1069 | F8: =C8/E8 -> 0.41908326 | G8: =D8/E8 -> 0.58091674
A9: Green Bay Packers | B9: GNB | C9: 479 | D9: 526 | E9: =SUM(C9:D9) -> 1005 | F9: =C9/E9 -> 0.47661692 | G9: =D9/E9 -> 0.52338308
A10: Minnesota Vikings | B10: MIN | C10: 548 | D10: 457 | E10: =SUM(C10:D10) -> 1005 | F10: =C10/E10 -> 0.54527363 | G10: =D10/E10 -> 0.45472637
A11: Denver Broncos | B11: DEN | C11: 570 | D11: 461 | E11: =SUM(C11:D11) -> 1031 | F11: =C11/E11 -> 0.5528613 | G11: =D11/E11 -> 0.4471387
A12: Los Angeles Chargers | B12: LAC | C12: 510 | D12: 463 | E12: =SUM(C12:D12) -> 973 | F12: =C12/E12 -> 0.52415211 | G12: =D12/E12 -> 0.47584789
A13: Arizona Cardinals | B13: ARI | C13: 543 | D13: 463 | E13: =SUM(C13:D13) -> 1006 | F13: =C13/E13 -> 0.53976143 | G13: =D13/E13 -> 0.46023857
... A33: Cleveland Browns | B33: CLE | C33: 661 | D33: 391 | E33: =SUM(C33:D33) -> 1052 | F33: =C33/E33 -> 0.628327 | G33: =D33/E33 -> 0.371673

Sheet 2023 Team
A1: Team | B1: ABB | C1: Pass Plays | D1: Run Plays | E1: Total Plays | F1: Pass % | G1: Run %
A2: Dallas Cowboys | B2: DAL | C2: 614 | D2: 468 | E2: =SUM(C2:D2) -> 1082 | F2: =C2/E2 -> 0.56746765 | G2: =D2/E2 -> 0.43253235
A3: Miami Dolphins | B3: MIA | C3: 566 | D3: 456 | E3: =SUM(C3:D3) -> 1022 | F3: =C3/E3 -> 0.55381605 | G3: =D3/E3 -> 0.44618395
A4: San Francisco 49ers | B4: SFO | C4: 491 | D4: 499 | E4: =SUM(C4:D4) -> 990 | F4: =C4/E4 -> 0.4959596 | G4: =D4/E4 -> 0.5040404
A5: Baltimore Ravens | B5: BAL | C5: 494 | D5: 541 | E5: =SUM(C5:D5) -> 1035 | F5: =C5/E5 -> 0.47729469 | G5: =D5/E5 -> 0.52270531
A6: Detroit Lions | B6: DET | C6: 606 | D6: 500 | E6: =SUM(C6:D6) -> 1106 | F6: =C6/E6 -> 0.54792043 | G6: =D6/E6 -> 0.45207957
A7: Buffalo Bills | B7: BUF | C7: 579 | D7: 512 | E7: =SUM(C7:D7) -> 1091 | F7: =C7/E7 -> 0.53070577 | G7: =D7/E7 -> 0.46929423
A8: Philadelphia Eagles | B8: PHI | C8: 563 | D8: 510 | E8: =SUM(C8:D8) -> 1073 | F8: =C8/E8 -> 0.52469711 | G8: =D8/E8 -> 0.47530289
A9: Los Angeles Rams | B9: LAR | C9: 583 | D9: 477 | E9: =SUM(C9:D9) -> 1060 | F9: =C9/E9 -> 0.55 | G9: =D9/E9 -> 0.45
A10: New Orleans Saints | B10: NOR | C10: 606 | D10: 480 | E10: =SUM(C10:D10) -> 1086 | F10: =C10/E10 -> 0.55801105 | G10: =D10/E10 -> 0.44198895
A11: Indianapolis Colts | B11: IND | C11: 574 | D11: 479 | E11: =SUM(C11:D11) -> 1053 | F11: =C11/E11 -> 0.54510921 | G11: =D11/E11 -> 0.45489079
A12: Cleveland Browns | B12: CLE | C12: 624 | D12: 518 | E12: =SUM(C12:D12) -> 1142 | F12: =C12/E12 -> 0.54640981 | G12: =D12/E12 -> 0.45359019
A13: Green Bay Packers | B13: GNB | C13: 581 | D13: 441 | E13: =SUM(C13:D13) -> 1022 | F13: =C13/E13 -> 0.56849315 | G13: =D13/E13 -> 0.43150685
... A33: Carolina Panthers | B33: CAR | C33: 586 | D33: 445 | E33: =SUM(C33:D33) -> 1031 | F33: =C33/E33 -> 0.56838021 | G33: =D33/E33 -> 0.43161979

Sheet 2022 Team
A1: Team | B1: ABB | C1: Pass Plays | D1: Run Plays | E1: Total Plays | F1: Pass % | G1: Run %
A2: Kansas City Chiefs | B2: KAN | C2: 651 | D2: 417 | E2: =SUM(C2:D2) -> 1068 | F2: =C2/E2 -> 0.60955056 | G2: =D2/E2 -> 0.39044944
A3: Philadelphia Eagles | B3: PHI | C3: 536 | D3: 544 | E3: =SUM(C3:D3) -> 1080 | F3: =C3/E3 -> 0.4962963 | G3: =D3/E3 -> 0.5037037
A4: Dallas Cowboys | B4: DAL | C4: 556 | D4: 531 | E4: =SUM(C4:D4) -> 1087 | F4: =C4/E4 -> 0.51149954 | G4: =D4/E4 -> 0.48850046
A5: Buffalo Bills | B5: BUF | C5: 574 | D5: 430 | E5: =SUM(C5:D5) -> 1004 | F5: =C5/E5 -> 0.57171315 | G5: =D5/E5 -> 0.42828685
A6: Detroit Lions | B6: DET | C6: 588 | D6: 480 | E6: =SUM(C6:D6) -> 1068 | F6: =C6/E6 -> 0.5505618 | G6: =D6/E6 -> 0.4494382
A7: San Francisco 49ers | B7: SFO | C7: 512 | D7: 504 | E7: =SUM(C7:D7) -> 1016 | F7: =C7/E7 -> 0.50393701 | G7: =D7/E7 -> 0.49606299
A8: Minnesota Vikings | B8: MIN | C8: 672 | D8: 404 | E8: =SUM(C8:D8) -> 1076 | F8: =C8/E8 -> 0.62453532 | G8: =D8/E8 -> 0.37546468
A9: Cincinnati Bengals | B9: CIN | C9: 610 | D9: 399 | E9: =SUM(C9:D9) -> 1009 | F9: =C9/E9 -> 0.60455897 | G9: =D9/E9 -> 0.39544103
A10: Seattle Seahawks | B10: SEA | C10: 573 | D10: 425 | E10: =SUM(C10:D10) -> 998 | F10: =C10/E10 -> 0.5741483 | G10: =D10/E10 -> 0.4258517
A11: Jacksonville Jaguars | B11: JAX | C11: 596 | D11: 448 | E11: =SUM(C11:D11) -> 1044 | F11: =C11/E11 -> 0.57088123 | G11: =D11/E11 -> 0.42911877
A12: Miami Dolphins | B12: MIA | C12: 584 | D12: 390 | E12: =SUM(C12:D12) -> 974 | F12: =C12/E12 -> 0.59958932 | G12: =D12/E12 -> 0.40041068
A13: Las Vegas Raiders | B13: LVR | C13: 586 | D13: 428 | E13: =SUM(C13:D13) -> 1014 | F13: =C13/E13 -> 0.57790927 | G13: =D13/E13 -> 0.42209073
... A33: Denver Broncos | B33: DEN | C33: 571 | D33: 444 | E33: =SUM(C33:D33) -> 1015 | F33: =C33/E33 -> 0.56256158 | G33: =D33/E33 -> 0.43743842

Sheet 2021 Team
A1: Team | B1: ABB | C1: Pass Plays | D1: Run Plays | E1: Total Plays | F1: Pass % | G1: Run %
A2: Dallas Cowboys | B2: DAL | C2: 647 | D2: 473 | E2: =SUM(C2:D2) -> 1120 | F2: =C2/E2 -> 0.57767857 | G2: =D2/E2 -> 0.42232143
A3: Tampa Bay Buccaneers | B3: TAM | C3: 731 | D3: 385 | E3: =SUM(C3:D3) -> 1116 | F3: =C3/E3 -> 0.65501792 | G3: =D3/E3 -> 0.34498208
A4: Buffalo Bills | B4: BUF | C4: 655 | D4: 461 | E4: =SUM(C4:D4) -> 1116 | F4: =C4/E4 -> 0.58691756 | G4: =D4/E4 -> 0.41308244
A5: Kansas City Chiefs | B5: KAN | C5: 675 | D5: 431 | E5: =SUM(C5:D5) -> 1106 | F5: =C5/E5 -> 0.61030741 | G5: =D5/E5 -> 0.38969259
A6: Los Angeles Chargers | B6: LAC | C6: 674 | D6: 423 | E6: =SUM(C6:D6) -> 1097 | F6: =C6/E6 -> 0.61440292 | G6: =D6/E6 -> 0.38559708
A7: New England Patriots | B7: NWE | C7: 535 | D7: 489 | E7: =SUM(C7:D7) -> 1024 | F7: =C7/E7 -> 0.52246094 | G7: =D7/E7 -> 0.47753906
A8: Cincinnati Bengals | B8: CIN | C8: 555 | D8: 436 | E8: =SUM(C8:D8) -> 991 | F8: =C8/E8 -> 0.56004036 | G8: =D8/E8 -> 0.43995964
A9: Los Angeles Rams | B9: LAR | C9: 607 | D9: 420 | E9: =SUM(C9:D9) -> 1027 | F9: =C9/E9 -> 0.59104187 | G9: =D9/E9 -> 0.40895813
A10: Indianapolis Colts | B10: IND | C10: 521 | D10: 499 | E10: =SUM(C10:D10) -> 1020 | F10: =C10/E10 -> 0.51078431 | G10: =D10/E10 -> 0.48921569
A11: Green Bay Packers | B11: GNB | C11: 593 | D11: 446 | E11: =SUM(C11:D11) -> 1039 | F11: =C11/E11 -> 0.5707411 | G11: =D11/E11 -> 0.4292589
A12: Arizona Cardinals | B12: ARI | C12: 591 | D12: 496 | E12: =SUM(C12:D12) -> 1087 | F12: =C12/E12 -> 0.54369825 | G12: =D12/E12 -> 0.45630175
A13: Philadelphia Eagles | B13: PHI | C13: 494 | D13: 550 | E13: =SUM(C13:D13) -> 1044 | F13: =C13/E13 -> 0.47318008 | G13: =D13/E13 -> 0.52681992
... A33: Jacksonville Jaguars | B33: JAX | C33: 604 | D33: 392 | E33: =SUM(C33:D33) -> 996 | F33: =C33/E33 -> 0.6064257 | G33: =D33/E33 -> 0.3935743

Sheet 2025 Passing
A1: Player | B1: Team | C1: Pos | D1: Cmp | E1: Att | F1: Cmp% | G1: Yds | H1: TD% | I1: Int% | J1: Y/A | K1: Passing Share
A2: Bo Nix | B2: DEN | C2: QB | D2: 388 | E2: 612 | F2: 63.4 | G2: 3931 | H2: 4.1 | I2: 1.8 | J2: 6.4 | K2: =E2/(VLOOKUP(B2,'2025 Team'!$B$2:$G$33,2,FALSE)) -> 0.99836868
A3: Dak Prescott | B3: DAL | C3: QB | D3: 404 | E3: 600 | F3: 67.3 | G3: 4552 | H3: 5 | I3: 1.7 | J3: 7.6 | K3: =E3/(VLOOKUP(B3,'2025 Team'!$B$2:$G$33,2,FALSE)) -> 0.96153846
A4: Matthew Stafford | B4: LAR | C4: QB | D4: 388 | E4: 597 | F4: 65 | G4: 4707 | H4: 7.7 | I4: 1.3 | J4: 7.9 | K4: =E4/(VLOOKUP(B4,'2025 Team'!$B$2:$G$33,2,FALSE)) -> 0.99832776
A5: Jared Goff | B5: DET | C5: QB | D5: 393 | E5: 578 | F5: 68 | G5: 4564 | H5: 5.9 | I5: 1.4 | J5: 7.9 | K5: =E5/(VLOOKUP(B5,'2025 Team'!$B$2:$G$33,2,FALSE)) -> 0.99312715
A6: Caleb Williams | B6: CHI | C6: QB | D6: 330 | E6: 568 | F6: 58.1 | G6: 3942 | H6: 4.8 | I6: 1.2 | J6: 6.9 | K6: =E6/(VLOOKUP(B6,'2025 Team'!$B$2:$G$33,2,FALSE)) -> 0.98954704
A7: Trevor Lawrence | B7: JAX | C7: QB | D7: 341 | E7: 560 | F7: 60.9 | G7: 4007 | H7: 5.2 | I7: 2.1 | J7: 7.2 | K7: =E7/(VLOOKUP(B7,'2025 Team'!$B$2:$G$33,2,FALSE)) -> 0.9946714
A8: Baker Mayfield | B8: TAM | C8: QB | D8: 343 | E8: 543 | F8: 63.2 | G8: 3693 | H8: 4.8 | I8: 2 | J8: 6.8 | K8: =E8/(VLOOKUP(B8,'2025 Team'!$B$2:$G$33,2,FALSE)) -> 0.97311828
A9: Cam Ward | B9: TEN | C9: QB | D9: 323 | E9: 540 | F9: 59.8 | G9: 3169 | H9: 2.8 | I9: 1.3 | J9: 5.9 | K9: =E9/(VLOOKUP(B9,'2025 Team'!$B$2:$G$33,2,FALSE)) -> 0.94736842
A10: Justin Herbert | B10: LAC | C10: QB | D10: 340 | E10: 512 | F10: 66.4 | G10: 3727 | H10: 5.1 | I10: 2.5 | J10: 7.3 | K10: =E10/(VLOOKUP(B10,'2025 Team'!$B$2:$G$33,2,FALSE)) -> 0.89982425
A11: Patrick Mahomes | B11: KAN | C11: QB | D11: 315 | E11: 502 | F11: 62.7 | G11: 3587 | H11: 4.4 | I11: 2.2 | J11: 7.1 | K11: =E11/(VLOOKUP(B11,'2025 Team'!$B$2:$G$33,2,FALSE)) -> 0.85958904
A12: Aaron Rodgers | B12: PIT | C12: QB | D12: 327 | E12: 498 | F12: 65.7 | G12: 3322 | H12: 4.8 | I12: 1.4 | J12: 6.7 | K12: =E12/(VLOOKUP(B12,'2025 Team'!$B$2:$G$33,2,FALSE)) -> 0.90545455
A13: Drake Maye | B13: NWE | C13: QB | D13: 354 | E13: 492 | F13: 72 | G13: 4394 | H13: 6.3 | I13: 1.6 | J13: 8.9 | K13: =E13/(VLOOKUP(B13,'2025 Team'!$B$2:$G$33,2,FALSE)) -> 0.98007968
... A98: Christian McCaffrey | B98: SFO | C98: RB | D98: 0 | E98: 1 | F98: 0 | G98: 0 | H98: 0 | I98: 0 | J98: 0 | K98: =E98/(VLOOKUP(B98,'2025 Team'!$B$2:$G$33,2,FALSE)) -> 0.0017421603
A99: Brett Rypien | B99: CIN | C99: QB | D99: 0 | E99: 0 | G99: 0 | K99: =E99/(VLOOKUP(B99,'2025 Team'!$B$2:$G$33,2,FALSE)) -> 0
A100: Courtland Sutton | B100: DEN | C100: WR | D100: 0 | E100: 0 | G100: 0 | K100: =E100/(VLOOKUP(B100,'2025 Team'!$B$2:$G$33,2,FALSE)) -> 0
A101: Marte Mapu | B101: NWE | C101: LB | D101: 0 | E101: 0 | G101: 0 | K101: =E101/(VLOOKUP(B101,'2025 Team'!$B$2:$G$33,2,FALSE)) -> 0
A102: Treylon Burks | B102: WAS | C102: WR | D102: 0 | E102: 0 | G102: 0 | K102: =E102/(VLOOKUP(B102,'2025 Team'!$B$2:$G$33,2,FALSE)) -> 0

Sheet 2024 Passing
A1: Player | B1: Team | C1: Pos | D1: Cmp | E1: Att | F1: Cmp% | G1: Yds | H1: TD% | I1: Int% | J1: Y/A | K1: Passing Share
A2: Joe Burrow | B2: CIN | C2: QB | D2: 460 | E2: 652 | F2: 70.6 | G2: 4918 | H2: 6.6 | I2: 1.4 | J2: 7.5 | K2: =E2/(VLOOKUP(B2,'2024 Team'!$B$2:$G$33,2,FALSE)) -> 1
A3: Jared Goff | B3: DET | C3: QB | D3: 390 | E3: 539 | F3: 72.4 | G3: 4629 | H3: 6.9 | I3: 2.2 | J3: 8.6 | K3: =E3/(VLOOKUP(B3,'2024 Team'!$B$2:$G$33,2,FALSE)) -> 0.97822142
A4: Baker Mayfield | B4: TAM | C4: QB | D4: 407 | E4: 570 | F4: 71.4 | G4: 4500 | H4: 7.2 | I4: 2.8 | J4: 7.9 | K4: =E4/(VLOOKUP(B4,'2024 Team'!$B$2:$G$33,2,FALSE)) -> 0.99824869
A5: Geno Smith | B5: SEA | C5: QB | D5: 407 | E5: 578 | F5: 70.4 | G5: 4320 | H5: 3.6 | I5: 2.6 | J5: 7.5 | K5: =E5/(VLOOKUP(B5,'2024 Team'!$B$2:$G$33,2,FALSE)) -> 0.97470489
A6: Sam Darnold | B6: MIN | C6: QB | D6: 361 | E6: 545 | F6: 66.2 | G6: 4319 | H6: 6.4 | I6: 2.2 | J6: 7.9 | K6: =E6/(VLOOKUP(B6,'2024 Team'!$B$2:$G$33,2,FALSE)) -> 0.99452555
A7: Lamar Jackson | B7: BAL | C7: QB | D7: 316 | E7: 474 | F7: 66.7 | G7: 4172 | H7: 8.6 | I7: 0.8 | J7: 8.8 | K7: =E7/(VLOOKUP(B7,'2024 Team'!$B$2:$G$33,2,FALSE)) -> 0.99371069
A8: Patrick Mahomes | B8: KAN | C8: QB | D8: 392 | E8: 581 | F8: 67.5 | G8: 3928 | H8: 4.5 | I8: 1.9 | J8: 6.8 | K8: =E8/(VLOOKUP(B8,'2024 Team'!$B$2:$G$33,2,FALSE)) -> 0.96833333
A9: Aaron Rodgers | B9: NYJ | C9: QB | D9: 368 | E9: 584 | F9: 63 | G9: 3897 | H9: 4.8 | I9: 1.9 | J9: 6.7 | K9: =E9/(VLOOKUP(B9,'2024 Team'!$B$2:$G$33,2,FALSE)) -> 0.96210873
A10: Justin Herbert | B10: LAC | C10: QB | D10: 332 | E10: 504 | F10: 65.9 | G10: 3870 | H10: 4.6 | I10: 0.6 | J10: 7.7 | K10: =E10/(VLOOKUP(B10,'2024 Team'!$B$2:$G$33,2,FALSE)) -> 0.98823529
A11: Brock Purdy | B11: SFO | C11: QB | D11: 300 | E11: 455 | F11: 65.9 | G11: 3864 | H11: 4.4 | I11: 2.6 | J11: 8.5 | K11: =E11/(VLOOKUP(B11,'2024 Team'!$B$2:$G$33,2,FALSE)) -> 0.85365854
A12: Kyler Murray | B12: ARI | C12: QB | D12: 372 | E12: 541 | F12: 68.8 | G12: 3851 | H12: 3.9 | I12: 2 | J12: 7.1 | K12: =E12/(VLOOKUP(B12,'2024 Team'!$B$2:$G$33,2,FALSE)) -> 0.99631676
A13: Bo Nix | B13: DEN | C13: QB | D13: 376 | E13: 567 | F13: 66.3 | G13: 3775 | H13: 5.1 | I13: 2.1 | J13: 6.7 | K13: =E13/(VLOOKUP(B13,'2024 Team'!$B$2:$G$33,2,FALSE)) -> 0.99473684
... A94: Tutu Atwell | B94: LAR | C94: WR | D94: 0 | E94: 1 | F94: 0 | G94: 0 | H94: 0 | I94: 0 | J94: 0 | K94: =E94/(VLOOKUP(B94,'2024 Team'!$B$2:$G$33,2,FALSE)) -> 0.0017889088
A95: Saquon Barkley | B95: PHI | C95: RB | D95: 0 | E95: 0 | G95: 0 | K95: =E95/(VLOOKUP(B95,'2024 Team'!$B$2:$G$33,2,FALSE)) -> 0
A96: Kendrick Bourne | B96: NWE | C96: WR | D96: 0 | E96: 1 | F96: 0 | G96: 0 | H96: 0 | I96: 0 | J96: 0 | K96: =E96/(VLOOKUP(B96,'2024 Team'!$B$2:$G$33,2,FALSE)) -> 0.0018903592
A97: Tyler Boyd | B97: TEN | C97: WR | D97: 0 | E97: 1 | F97: 0 | G97: 0 | H97: 0 | I97: 0 | J97: 0 | K97: =E97/(VLOOKUP(B97,'2024 Team'!$B$2:$G$33,2,FALSE)) -> 0.0018867925
A98: Dyami Brown | B98: WAS | C98: WR | D98: 0 | E98: 1 | F98: 0 | G98: 0 | H98: 0 | I98: 0 | J98: 0 | K98: =E98/(VLOOKUP(B98,'2024 Team'!$B$2:$G$33,2,FALSE)) -> 0.0019047619
A99: Ty Chandler | B99: MIN | C99: RB | D99: 0 | E99: 0 | G99: 0 | K99: =E99/(VLOOKUP(B99,'2024 Team'!$B$2:$G$33,2,FALSE)) -> 0
A100: Johnny Hekker | B100: CAR | C100: P | D100: 0 | E100: 2 | F100: 0 | G100: 0 | H100: 0 | I100: 0 | J100: 0 | K100: =E100/(VLOOKUP(B100,'2024 Team'!$B$2:$G$33,2,FALSE)) -> 0.0036563071
A101: Miles Killebrew | B101: PIT | C101: S | D101: 0 | E101: 1 | F101: 0 | G101: 0 | H101: 0 | I101: 0 | J101: 0 | K101: =E101/(VLOOKUP(B101,'2024 Team'!$B$2:$G$33,2,FALSE)) -> 0.002004008
A102: Allen Lazard | B102: NYJ | C102: WR | D102: 0 | E102: 1 | F102: 0 | G102: 0 | H102: 0 | I102: 0 | J102: 0 | K102: =E102/(VLOOKUP(B102,'2024 Team'!$B$2:$G$33,2,FALSE)) -> 0.0016474465
A103: Jakobi Meyers | B103: LVR | C103: WR | D103: 0 | E103: 0 | G103: 0 | K103: =E103/(VLOOKUP(B103,'2024 Team'!$B$2:$G$33,2,FALSE)) -> 0
A104: Joe Mixon | B104: HOU | C104: RB | D104: 0 | E104: 1 | F104: 0 | G104: 0 | H104: 0 | I104: 0 | J104: 0 | K104: =E104/(VLOOKUP(B104,'2024 Team'!$B$2:$G$33,2,FALSE)) -> 0.001754386
A105: Darnell Mooney | B105: ATL | C105: WR | D105: 0 | E105: 1 | F105: 0 | G105: 0 | H105: 0 | I105: 0 | J105: 0 | K105: =E105/(VLOOKUP(B105,'2024 Team'!$B$2:$G$33,2,FALSE)) -> 0.0017889088
A106: D.J. Moore | B106: CHI | C106: WR | D106: 0 | E106: 1 | F106: 0 | G106: 0 | H106: 0 | I106: 0 | J106: 0 | K106: =E106/(VLOOKUP(B106,'2024 Team'!$B$2:$G$33,2,FALSE)) -> 0.0017667845
A107: Malik Nabers | B107: NYG | C107: WR | D107: 0 | E107: 1 | F107: 0 | G107: 0 | H107: 0 | I107: 0 | J107: 0 | K107: =E107/(VLOOKUP(B107,'2024 Team'!$B$2:$G$33,2,FALSE)) -> 0.0016920474
A108: Chris Oladokun | B108: KAN | C108: QB | D108: 0 | E108: 0 | G108: 0 | K108: =E108/(VLOOKUP(B108,'2024 Team'!$B$2:$G$33,2,FALSE)) -> 0
A109: Ricky Pearsall | B109: SFO | C109: WR | D109: 0 | E109: 1 | F109: 0 | G109: 0 | H109: 0 | I109: 0 | J109: 0 | K109: =E109/(VLOOKUP(B109,'2024 Team'!$B$2:$G$33,2,FALSE)) -> 0.0018761726
A110: Deebo Samuel | B110: SFO | C110: WR | D110: 0 | E110: 0 | G110: 0 | K110: =E110/(VLOOKUP(B110,'2024 Team'!$B$2:$G$33,2,FALSE)) -> 0
A111: Penei Sewell | B111: DET | C111: RT | D111: 0 | E111: 0 | G111: 0 | K111: =E111/(VLOOKUP(B111,'2024 Team'!$B$2:$G$33,2,FALSE)) -> 0
A112: League Average | F112: 65.3 | H112: 4.5 | I112: 2.2 | J112: 7.1 | K112: =E112/(VLOOKUP(B112,'2024 Team'!$B$2:$G$33,2,FALSE)) -> #N/A

Sheet 2023 Passing
A1: Player | B1: Team | C1: Pos | D1: Cmp | E1: Att | F1: Cmp% | G1: Yds | H1: TD% | I1: Int% | J1: Y/A | K1: Passing Share
A2: Tua Tagovailoa | B2: MIA | C2: QB | D2: 388 | E2: 560 | F2: 69.3 | G2: 4624 | H2: 5.2 | I2: 2.5 | J2: 8.3 | K2: =E2/(VLOOKUP(B2,'2023 Team'!$B$2:$G$33,2,FALSE)) -> 0.98939929
A3: Jared Goff | B3: DET | C3: QB | D3: 407 | E3: 605 | F3: 67.3 | G3: 4575 | H3: 5 | I3: 2 | J3: 7.6 | K3: =E3/(VLOOKUP(B3,'2023 Team'!$B$2:$G$33,2,FALSE)) -> 0.99834983
A4: Dak Prescott | B4: DAL | C4: QB | D4: 410 | E4: 590 | F4: 69.5 | G4: 4516 | H4: 6.1 | I4: 1.5 | J4: 7.7 | K4: =E4/(VLOOKUP(B4,'2023 Team'!$B$2:$G$33,2,FALSE)) -> 0.96091205
A5: Josh Allen | B5: BUF | C5: QB | D5: 385 | E5: 579 | F5: 66.5 | G5: 4306 | H5: 5 | I5: 3.1 | J5: 7.4 | K5: =E5/(VLOOKUP(B5,'2023 Team'!$B$2:$G$33,2,FALSE)) -> 1
A6: Brock Purdy | B6: SFO | C6: QB | D6: 308 | E6: 444 | F6: 69.4 | G6: 4280 | H6: 7 | I6: 2.5 | J6: 9.6 | K6: =E6/(VLOOKUP(B6,'2023 Team'!$B$2:$G$33,2,FALSE)) -> 0.90427699
A7: Patrick Mahomes | B7: KAN | C7: QB | D7: 401 | E7: 597 | F7: 67.2 | G7: 4183 | H7: 4.5 | I7: 2.3 | J7: 7 | K7: =E7/(VLOOKUP(B7,'2023 Team'!$B$2:$G$33,2,FALSE)) -> 0.94015748
A8: Jordan Love | B8: GNB | C8: QB | D8: 372 | E8: 579 | F8: 64.2 | G8: 4159 | H8: 5.5 | I8: 1.9 | J8: 7.2 | K8: =E8/(VLOOKUP(B8,'2023 Team'!$B$2:$G$33,2,FALSE)) -> 0.99655766
A9: C.J. Stroud | B9: HOU | C9: QB | D9: 319 | E9: 499 | F9: 63.9 | G9: 4108 | H9: 4.6 | I9: 1 | J9: 8.2 | K9: =E9/(VLOOKUP(B9,'2023 Team'!$B$2:$G$33,2,FALSE)) -> 0.84290541
A10: Baker Mayfield | B10: TAM | C10: QB | D10: 364 | E10: 566 | F10: 64.3 | G10: 4044 | H10: 4.9 | I10: 1.8 | J10: 7.1 | K10: =E10/(VLOOKUP(B10,'2023 Team'!$B$2:$G$33,2,FALSE)) -> 0.99647887
A11: Trevor Lawrence | B11: JAX | C11: QB | D11: 370 | E11: 564 | F11: 65.6 | G11: 4016 | H11: 3.7 | I11: 2.5 | J11: 7.1 | K11: =E11/(VLOOKUP(B11,'2023 Team'!$B$2:$G$33,2,FALSE)) -> 0.90967742
A12: Matthew Stafford | B12: LAR | C12: QB | D12: 326 | E12: 521 | F12: 62.6 | G12: 3965 | H12: 4.6 | I12: 2.1 | J12: 7.6 | K12: =E12/(VLOOKUP(B12,'2023 Team'!$B$2:$G$33,2,FALSE)) -> 0.89365352
A13: Sam Howell | B13: WAS | C13: QB | D13: 388 | E13: 612 | F13: 63.4 | G13: 3946 | H13: 3.4 | I13: 3.4 | J13: 6.4 | K13: =E13/(VLOOKUP(B13,'2023 Team'!$B$2:$G$33,2,FALSE)) -> 0.96226415
... A93: Jerick McKinnon | B93: KAN | C93: RB | D93: 1 | E93: 1 | F93: 100 | G93: 4 | H93: 100 | I93: 0 | J93: 4 | K93: =E93/(VLOOKUP(B93,'2023 Team'!$B$2:$G$33,2,FALSE)) -> 0.0015748031
A94: De'Von Achane | B94: MIA | C94: RB | D94: 0 | E94: 0 | G94: 0 | K94: =E94/(VLOOKUP(B94,'2023 Team'!$B$2:$G$33,2,FALSE)) -> 0
A95: Cam Akers | B95: MIN | C95: RB | D95: 0 | E95: 0 | G95: 0 | K95: =E95/(VLOOKUP(B95,'2023 Team'!$B$2:$G$33,2,FALSE)) -> 0
A96: Tyler Boyd | B96: CIN | C96: WR | D96: 0 | E96: 1 | F96: 0 | G96: 0 | H96: 0 | I96: 100 | J96: 0 | K96: =E96/(VLOOKUP(B96,'2023 Team'!$B$2:$G$33,2,FALSE)) -> 0.0016260163
A97: Parris Campbell | B97: NYG | C97: WR | D97: 0 | E97: 0 | G97: 0 | K97: =E97/(VLOOKUP(B97,'2023 Team'!$B$2:$G$33,2,FALSE)) -> 0
A98: Malik Cunningham | B98: NWE | C98: QB | D98: 0 | E98: 0 | G98: 0 | K98: =E98/(VLOOKUP(B98,'2023 Team'!$B$2:$G$33,2,FALSE)) -> 0
A99: DeeJay Dallas | B99: SEA | C99: RB | D99: 0 | E99: 0 | G99: 0 | K99: =E99/(VLOOKUP(B99,'2023 Team'!$B$2:$G$33,2,FALSE)) -> 0
A100: Tank Dell | B100: HOU | C100: WR | D100: 0 | E100: 0 | G100: 0 | K100: =E100/(VLOOKUP(B100,'2023 Team'!$B$2:$G$33,2,FALSE)) -> 0
A101: Chris Godwin | B101: TAM | C101: WR | D101: 0 | E101: 1 | F101: 0 | G101: 0 | H101: 0 | I101: 0 | J101: 0 | K101: =E101/(VLOOKUP(B101,'2023 Team'!$B$2:$G$33,2,FALSE)) -> 0.0017605634
A102: Connor Heyward | B102: PIT | C102: TE | D102: 0 | E102: 1 | F102: 0 | G102: 0 | H102: 0 | I102: 0 | J102: 0 | K102: =E102/(VLOOKUP(B102,'2023 Team'!$B$2:$G$33,2,FALSE)) -> 0.0019762846
A103: DeAndre Hopkins | B103: TEN | C103: WR | D103: 0 | E103: 1 | F103: 0 | G103: 0 | H103: 0 | I103: 0 | J103: 0 | K103: =E103/(VLOOKUP(B103,'2023 Team'!$B$2:$G$33,2,FALSE)) -> 0.0020242915
A104: Tanner Hudson | B104: CIN | C104: TE | D104: 0 | E104: 0 | G104: 0 | K104: =E104/(VLOOKUP(B104,'2023 Team'!$B$2:$G$33,2,FALSE)) -> 0
A105: Josh Jacobs | B105: LVR | C105: RB | D105: 0 | E105: 0 | G105: 0 | K105: =E105/(VLOOKUP(B105,'2023 Team'!$B$2:$G$33,2,FALSE)) -> 0
A106: Justin Jefferson | B106: MIN | C106: WR | D106: 0 | E106: 1 | F106: 0 | G106: 0 | H106: 0 | I106: 0 | J106: 0 | K106: =E106/(VLOOKUP(B106,'2023 Team'!$B$2:$G$33,2,FALSE)) -> 0.0015847861
A107: Nathan Peterman | B107: CHI | C107: QB | D107: 0 | E107: 0 | G107: 0 | K107: =E107/(VLOOKUP(B107,'2023 Team'!$B$2:$G$33,2,FALSE)) -> 0
A108: Aaron Rodgers | B108: NYJ | C108: QB | D108: 0 | E108: 1 | F108: 0 | G108: 0 | H108: 0 | I108: 0 | J108: 0 | K108: =E108/(VLOOKUP(B108,'2023 Team'!$B$2:$G$33,2,FALSE)) -> 0.0016638935
A109: Deebo Samuel | B109: SFO | C109: WR | D109: 0 | E109: 1 | F109: 0 | G109: 0 | H109: 0 | I109: 0 | J109: 0 | K109: =E109/(VLOOKUP(B109,'2023 Team'!$B$2:$G$33,2,FALSE)) -> 0.0020366599
A110: Jonnu Smith | B110: ATL | C110: TE | D110: 0 | E110: 1 | F110: 0 | G110: 0 | H110: 0 | I110: 0 | J110: 0 | K110: =E110/(VLOOKUP(B110,'2023 Team'!$B$2:$G$33,2,FALSE)) -> 0.0018867925
A111: Amon-Ra St. Brown | B111: DET | C111: WR | D111: 0 | E111: 0 | G111: 0 | K111: =E111/(VLOOKUP(B111,'2023 Team'!$B$2:$G$33,2,FALSE)) -> 0
A112: Kadarius Toney | B112: KAN | C112: WR | D112: 0 | E112: 1 | F112: 0 | G112: 0 | H112: 0 | I112: 0 | J112: 0 | K112: =E112/(VLOOKUP(B112,'2023 Team'!$B$2:$G$33,2,FALSE)) -> 0.0015748031
A113: Kyle Trask | B113: TAM | C113: QB | D113: 0 | E113: 1 | F113: 0 | G113: 0 | H113: 0 | I113: 0 | J113: 0 | K113: =E113/(VLOOKUP(B113,'2023 Team'!$B$2:$G$33,2,FALSE)) -> 0.0017605634
A114: Cedrick Wilson Jr. | B114: MIA | C114: WR | D114: 0 | E114: 0 | G114: 0 | K114: =E114/(VLOOKUP(B114,'2023 Team'!$B$2:$G$33,2,FALSE)) -> 0
A115: Garrett Wilson | B115: NYJ | C115: WR | D115: 0 | E115: 1 | F115: 0 | G115: 0 | H115: 0 | I115: 0 | J115: 0 | K115: =E115/(VLOOKUP(B115,'2023 Team'!$B$2:$G$33,2,FALSE)) -> 0.0016638935
A116: Christian Kirk | B116: JAX | C116: WR | D116: 1 | E116: 2 | F116: 50 | G116: -1 | H116: 0 | I116: 0 | J116: -0.5 | K116: =E116/(VLOOKUP(B116,'2023 Team'!$B$2:$G$33,2,FALSE)) -> 0.0032258065
A117: Ja'Marr Chase | B117: CIN | C117: WR | D117: 1 | E117: 1 | F117: 100 | G117: -7 | H117: 0 | I117: 0 | J117: -7 | K117: =E117/(VLOOKUP(B117,'2023 Team'!$B$2:$G$33,2,FALSE)) -> 0.0016260163
A118: League Average | F118: 64.5 | H118: 4.1 | I118: 2.3 | J118: 7 | K118: =E118/(VLOOKUP(B118,'2023 Team'!$B$2:$G$33,2,FALSE)) -> #N/A

Sheet 2022 Passing
A1: Player | B1: Team | C1: Pos | D1: Cmp | E1: Att | F1: Cmp% | G1: Yds | H1: TD% | I1: Int% | J1: Y/A | K1: Passing Share
A2: Patrick Mahomes | B2: KAN | C2: QB | D2: 435 | E2: 648 | F2: 67.1 | G2: 188 | H2: 6.3 | I2: 1.9 | J2: 8.1 | K2: =E2/(VLOOKUP(B2,'[1]2022 Team'!$B$2:$G$33,2,FALSE)) -> 0.99539171
A3: Justin Herbert | B3: LAC | C3: QB | D3: 477 | E3: 699 | F3: 68.2 | G3: 206 | H3: 3.6 | I3: 1.4 | J3: 6.8 | K3: =E3/(VLOOKUP(B3,'[1]2022 Team'!$B$2:$G$33,2,FALSE)) -> 0.98312236
A4: Tom Brady | B4: TAM | C4: QB | D4: 490 | E4: 733 | F4: 66.8 | G4: 160 | H4: 3.4 | I4: 1.2 | J4: 6.4 | K4: =E4/(VLOOKUP(B4,'[1]2022 Team'!$B$2:$G$33,2,FALSE)) -> 0.97603196
A5: Kirk Cousins | B5: MIN | C5: QB | D5: 424 | E5: 643 | F5: 65.9 | G5: 329 | H5: 4.5 | I5: 2.2 | J5: 7.1 | K5: =E5/(VLOOKUP(B5,'[1]2022 Team'!$B$2:$G$33,2,FALSE)) -> 0.95684524
A6: Joe Burrow | B6: CIN | C6: QB | D6: 414 | E6: 606 | F6: 68.3 | G6: 259 | H6: 5.8 | I6: 2 | J6: 7.4 | K6: =E6/(VLOOKUP(B6,'[1]2022 Team'!$B$2:$G$33,2,FALSE)) -> 0.99344262
A7: Jared Goff | B7: DET | C7: QB | D7: 382 | E7: 587 | F7: 65.1 | G7: 156 | H7: 4.9 | I7: 1.2 | J7: 7.6 | K7: =E7/(VLOOKUP(B7,'[1]2022 Team'!$B$2:$G$33,2,FALSE)) -> 0.99829932
A8: Josh Allen | B8: BUF | C8: QB | D8: 359 | E8: 567 | F8: 63.3 | G8: 162 | H8: 6.2 | I8: 2.5 | J8: 7.6 | K8: =E8/(VLOOKUP(B8,'[1]2022 Team'!$B$2:$G$33,2,FALSE)) -> 0.98780488
A9: Geno Smith | B9: SEA | C9: QB | D9: 399 | E9: 572 | F9: 69.8 | G9: 348 | H9: 5.2 | I9: 1.9 | J9: 7.5 | K9: =E9/(VLOOKUP(B9,'[1]2022 Team'!$B$2:$G$33,2,FALSE)) -> 0.9982548
A10: Trevor Lawrence | B10: JAX | C10: QB | D10: 387 | E10: 584 | F10: 66.3 | G10: 184 | H10: 4.3 | I10: 1.4 | J10: 7 | K10: =E10/(VLOOKUP(B10,'[1]2022 Team'!$B$2:$G$33,2,FALSE)) -> 0.97986577
A11: Jalen Hurts | B11: PHI | C11: QB | D11: 306 | E11: 460 | F11: 66.5 | G11: 231 | H11: 4.8 | I11: 1.3 | J11: 8 | K11: =E11/(VLOOKUP(B11,'[1]2022 Team'!$B$2:$G$33,2,FALSE)) -> 0.85820896
A12: Aaron Rodgers | B12: GNB | C12: QB | D12: 350 | E12: 542 | F12: 64.6 | G12: 258 | H12: 4.8 | I12: 2.2 | J12: 6.8 | K12: =E12/(VLOOKUP(B12,'[1]2022 Team'!$B$2:$G$33,2,FALSE)) -> 0.96269982
A13: Tua Tagovailoa | B13: MIA | C13: QB | D13: 259 | E13: 400 | F13: 64.8 | G13: 163 | H13: 6.3 | I13: 2 | J13: 8.9 | K13: =E13/(VLOOKUP(B13,'[1]2022 Team'!$B$2:$G$33,2,FALSE)) -> 0.68493151
... A97: Chase Claypool | B97: PIT | C97: WR | D97: 1 | E97: 1 | F97: 100 | G97: 0 | H97: 100 | I97: 0 | J97: 1 | K97: =E97/(VLOOKUP(B97,'[1]2022 Team'!$B$2:$G$33,2,FALSE)) -> 0.0017513135
A98: Davante Adams | B98: LVR | C98: WR | D98: 0 | E98: 0 | G98: 10 | K98: =E98/(VLOOKUP(B98,'[1]2022 Team'!$B$2:$G$33,2,FALSE)) -> 0
A99: Rex Burkhead | B99: HOU | C99: RB | D99: 0 | E99: 1 | F99: 0 | G99: 0 | H99: 0 | I99: 0 | J99: 0 | K99: =E99/(VLOOKUP(B99,'[1]2022 Team'!$B$2:$G$33,2,FALSE)) -> 0.0017271157
A100: Lawrence Cager | B100: NYG | C100: WR | D100: 0 | E100: 0 | G100: 2 | K100: =E100/(VLOOKUP(B100,'[1]2022 Team'!$B$2:$G$33,2,FALSE)) -> 0
A101: Ja'Marr Chase | B101: CIN | C101: WR | D101: 0 | E101: 0 | G101: 9 | K101: =E101/(VLOOKUP(B101,'[1]2022 Team'!$B$2:$G$33,2,FALSE)) -> 0
A102: Dalvin Cook | B102: MIN | C102: RB | D102: 0 | E102: 0 | G102: 5 | K102: =E102/(VLOOKUP(B102,'[1]2022 Team'!$B$2:$G$33,2,FALSE)) -> 0
A103: Amari Cooper | B103: CLE | C103: WR | D103: 0 | E103: 1 | F103: 0 | G103: 0 | H103: 0 | I103: 100 | J103: 0 | K103: =E103/(VLOOKUP(B103,'[1]2022 Team'!$B$2:$G$33,2,FALSE)) -> 0.0018518519
A104: DeeJay Dallas | B104: SEA | C104: RB | D104: 0 | E104: 1 | F104: 0 | G104: 0 | H104: 0 | I104: 100 | J104: 0 | K104: =E104/(VLOOKUP(B104,'[1]2022 Team'!$B$2:$G$33,2,FALSE)) -> 0.0017452007
A105: Phillip Dorsett | B105: HOU | C105: WR | D105: 0 | E105: 1 | F105: 0 | G105: 0 | H105: 0 | I105: 0 | J105: 0 | K105: =E105/(VLOOKUP(B105,'[1]2022 Team'!$B$2:$G$33,2,FALSE)) -> 0.0017271157
A106: Leonard Fournette | B106: TAM | C106: RB | D106: 0 | E106: 1 | F106: 0 | G106: 0 | H106: 0 | I106: 100 | J106: 0 | K106: =E106/(VLOOKUP(B106,'[1]2022 Team'!$B$2:$G$33,2,FALSE)) -> 0.0013315579
A107: Jamie Gillan | B107: NYG | C107: P | D107: 0 | E107: 0 | G107: 11 | K107: =E107/(VLOOKUP(B107,'[1]2022 Team'!$B$2:$G$33,2,FALSE)) -> 0
A108: Chad Henne | B108: KAN | C108: QB | D108: 0 | E108: 2 | F108: 0 | G108: 0 | H108: 0 | I108: 0 | J108: 0 | K108: =E108/(VLOOKUP(B108,'[1]2022 Team'!$B$2:$G$33,2,FALSE)) -> 0.0030721966
A109: Christian Kirk | B109: JAX | C109: WR | D109: 0 | E109: 1 | F109: 0 | G109: 0 | H109: 0 | I109: 0 | J109: 0 | K109: =E109/(VLOOKUP(B109,'[1]2022 Team'!$B$2:$G$33,2,FALSE)) -> 0.0016778523
A110: Cooper Kupp | B110: LAR | C110: WR | D110: 0 | E110: 1 | F110: 0 | G110: 0 | H110: 0 | I110: 0 | J110: 0 | K110: =E110/(VLOOKUP(B110,'[1]2022 Team'!$B$2:$G$33,2,FALSE)) -> 0.0018832392
A111: James Proche | B111: BAL | C111: WR | D111: 0 | E111: 1 | F111: 0 | G111: 0 | H111: 0 | I111: 100 | J111: 0 | K111: =E111/(VLOOKUP(B111,'[1]2022 Team'!$B$2:$G$33,2,FALSE)) -> 0.0020491803
A112: Nate Sudfeld | B112: DET | C112: QB | D112: 0 | E112: 0 | G112: 7 | K112: =E112/(VLOOKUP(B112,'[1]2022 Team'!$B$2:$G$33,2,FALSE)) -> 0
A113: Tommy Townsend | B113: KAN | C113: P | D113: 0 | E113: 1 | F113: 0 | G113: 0 | H113: 0 | I113: 0 | J113: 0 | K113: =E113/(VLOOKUP(B113,'[1]2022 Team'!$B$2:$G$33,2,FALSE)) -> 0.0015360983
A114: Cedrick Wilson Jr. | B114: MIA | C114: WR | D114: 0 | E114: 0 | G114: 6 | K114: =E114/(VLOOKUP(B114,'[1]2022 Team'!$B$2:$G$33,2,FALSE)) -> 0
A115: Garrett Wilson | B115: NYJ | C115: WR | D115: 0 | E115: 1 | F115: 0 | G115: 0 | H115: 0 | I115: 0 | J115: 0 | K115: =E115/(VLOOKUP(B115,'[1]2022 Team'!$B$2:$G$33,2,FALSE)) -> 0.0015948963

Sheet 2021 Passing
A1: Player | B1: Team | C1: Pos | D1: Cmp | E1: Att | F1: Cmp% | G1: Yds | H1: TD% | I1: Int% | J1: Y/A | K1: Passing Share
A2: Tom Brady | B2: TAM | C2: QB | D2: 485 | E2: 719 | F2: 67.5 | G2: 144 | H2: 6 | I2: 1.7 | J2: 7.4 | K2: =E2/(VLOOKUP(B2,'[1]2021 Team'!$B$2:$G$33,2,FALSE)) -> 0.98358413
A3: Justin Herbert | B3: LAC | C3: QB | D3: 443 | E3: 672 | F3: 65.9 | G3: 214 | H3: 5.7 | I3: 2.2 | J3: 7.5 | K3: =E3/(VLOOKUP(B3,'[1]2021 Team'!$B$2:$G$33,2,FALSE)) -> 0.99703264
A4: Matthew Stafford | B4: LAR | C4: QB | D4: 404 | E4: 601 | F4: 67.2 | G4: 243 | H4: 6.8 | I4: 2.8 | J4: 8.1 | K4: =E4/(VLOOKUP(B4,'[1]2021 Team'!$B$2:$G$33,2,FALSE)) -> 0.99011532
A5: Patrick Mahomes | B5: KAN | C5: QB | D5: 436 | E5: 658 | F5: 66.3 | G5: 146 | H5: 5.6 | I5: 2 | J5: 7.4 | K5: =E5/(VLOOKUP(B5,'[1]2021 Team'!$B$2:$G$33,2,FALSE)) -> 0.97481481
A6: Derek Carr | B6: LVR | C6: QB | D6: 428 | E6: 626 | F6: 68.4 | G6: 241 | H6: 3.7 | I6: 2.2 | J6: 7.7 | K6: =E6/(VLOOKUP(B6,'[1]2021 Team'!$B$2:$G$33,2,FALSE)) -> 0.99681529
A7: Joe Burrow | B7: CIN | C7: QB | D7: 366 | E7: 520 | F7: 70.4 | G7: 370 | H7: 6.5 | I7: 2.7 | J7: 8.9 | K7: =E7/(VLOOKUP(B7,'[1]2021 Team'!$B$2:$G$33,2,FALSE)) -> 0.93693694
A8: Dak Prescott | B8: DAL | C8: QB | D8: 410 | E8: 596 | F8: 68.8 | G8: 144 | H8: 6.2 | I8: 1.7 | J8: 7.5 | K8: =E8/(VLOOKUP(B8,'[1]2021 Team'!$B$2:$G$33,2,FALSE)) -> 0.92117465
A9: Josh Allen | B9: BUF | C9: QB | D9: 409 | E9: 646 | F9: 63.3 | G9: 164 | H9: 5.6 | I9: 2.3 | J9: 6.8 | K9: =E9/(VLOOKUP(B9,'[1]2021 Team'!$B$2:$G$33,2,FALSE)) -> 0.98625954
A10: Kirk Cousins | B10: MIN | C10: QB | D10: 372 | E10: 561 | F10: 66.3 | G10: 197 | H10: 5.9 | I10: 1.2 | J10: 7.5 | K10: =E10/(VLOOKUP(B10,'[1]2021 Team'!$B$2:$G$33,2,FALSE)) -> 0.92880795
A11: Aaron Rodgers | B11: GNB | C11: QB | D11: 366 | E11: 531 | F11: 68.9 | G11: 188 | H11: 7 | I11: 0.8 | J11: 7.7 | K11: =E11/(VLOOKUP(B11,'[1]2021 Team'!$B$2:$G$33,2,FALSE)) -> 0.89544688
A12: Matt Ryan | B12: ATL | C12: QB | D12: 375 | E12: 560 | F12: 67 | G12: 274 | H12: 3.6 | I12: 2.1 | J12: 7.1 | K12: =E12/(VLOOKUP(B12,'[1]2021 Team'!$B$2:$G$33,2,FALSE)) -> 0.97731239
A13: Jimmy Garoppolo | B13: SFO | C13: QB | D13: 301 | E13: 441 | F13: 68.3 | G13: 201 | H13: 4.5 | I13: 2.7 | J13: 8.6 | K13: =E13/(VLOOKUP(B13,'[1]2021 Team'!$B$2:$G$33,2,FALSE)) -> 0.85797665
... A99: Cole Beasley | B99: BUF | C99: WR | D99: 0 | E99: 1 | F99: 0 | G99: 0 | H99: 0 | I99: 0 | J99: 0 | K99: =E99/(VLOOKUP(B99,'[1]2021 Team'!$B$2:$G$33,2,FALSE)) -> 0.0015267176
A100: David Blough | B100: DET | C100: QB | D100: 0 | E100: 0 | G100: 6 | K100: =E100/(VLOOKUP(B100,'[1]2021 Team'!$B$2:$G$33,2,FALSE)) -> 0
A101: Chris Boswell | B101: PIT | C101: K | D101: 0 | E101: 1 | F101: 0 | G101: 0 | H101: 0 | I101: 0 | J101: 0 | K101: =E101/(VLOOKUP(B101,'[1]2021 Team'!$B$2:$G$33,2,FALSE)) -> 0.0015060241
A102: A.J. Brown | B102: TEN | C102: WR | D102: 0 | E102: 2 | F102: 0 | G102: 0 | H102: 0 | I102: 0 | J102: 0 | K102: =E102/(VLOOKUP(B102,'[1]2021 Team'!$B$2:$G$33,2,FALSE)) -> 0.0037383178
A103: Rex Burkhead | B103: HOU | C103: RB | D103: 0 | E103: 1 | F103: 0 | G103: 0 | H103: 0 | I103: 0 | J103: 0 | K103: =E103/(VLOOKUP(B103,'[1]2021 Team'!$B$2:$G$33,2,FALSE)) -> 0.0018315018
A104: Keelan Cole | B104: NYJ | C104: WR | D104: 0 | E104: 1 | F104: 0 | G104: 0 | H104: 0 | I104: 0 | J104: 0 | K104: =E104/(VLOOKUP(B104,'[1]2021 Team'!$B$2:$G$33,2,FALSE)) -> 0.0016583748
A105: Jamison Crowder | B105: NYJ | C105: WR | D105: 0 | E105: 0 | G105: 3 | K105: =E105/(VLOOKUP(B105,'[1]2021 Team'!$B$2:$G$33,2,FALSE)) -> 0
A106: Stefon Diggs | B106: BUF | C106: WR | D106: 0 | E106: 0 | G106: 2 | K106: =E106/(VLOOKUP(B106,'[1]2021 Team'!$B$2:$G$33,2,FALSE)) -> 0
A107: Riley Dixon | B107: NYG | C107: P | D107: 0 | E107: 1 | F107: 0 | G107: 0 | H107: 0 | I107: 0 | J107: 0 | K107: =E107/(VLOOKUP(B107,'[1]2021 Team'!$B$2:$G$33,2,FALSE)) -> 0.0016863406
A108: Leonard Fournette | B108: TAM | C108: RB | D108: 0 | E108: 1 | F108: 0 | G108: 0 | H108: 0 | I108: 0 | J108: 0 | K108: =E108/(VLOOKUP(B108,'[1]2021 Team'!$B$2:$G$33,2,FALSE)) -> 0.0013679891
A109: Feleipe Franks | B109: ATL | C109: QB | D109: 0 | E109: 1 | F109: 0 | G109: 0 | H109: 0 | I109: 100 | J109: 0 | K109: =E109/(VLOOKUP(B109,'[1]2021 Team'!$B$2:$G$33,2,FALSE)) -> 0.0017452007
A110: Mike Gesicki | B110: MIA | C110: TE | D110: 0 | E110: 1 | F110: 0 | G110: 0 | H110: 0 | I110: 0 | J110: 0 | K110: =E110/(VLOOKUP(B110,'[1]2021 Team'!$B$2:$G$33,2,FALSE)) -> 0.0016260163
A111: Blake Gillikin | B111: NOR | C111: P | D111: 0 | E111: 1 | F111: 0 | G111: 0 | H111: 0 | I111: 0 | J111: 0 | K111: =E111/(VLOOKUP(B111,'[1]2021 Team'!$B$2:$G$33,2,FALSE)) -> 0.001984127
A112: Sam Koch | B112: BAL | C112: P | D112: 0 | E112: 1 | F112: 0 | G112: 0 | H112: 0 | I112: 0 | J112: 0 | K112: =E112/(VLOOKUP(B112,'[1]2021 Team'!$B$2:$G$33,2,FALSE)) -> 0.0016366612
A113: Cooper Kupp | B113: LAR | C113: WR | D113: 0 | E113: 1 | F113: 0 | G113: 0 | H113: 0 | I113: 0 | J113: 0 | K113: =E113/(VLOOKUP(B113,'[1]2021 Team'!$B$2:$G$33,2,FALSE)) -> 0.0016474465
A114: Jarvis Landry | B114: CLE | C114: WR | D114: 0 | E114: 0 | G114: 1 | K114: =E114/(VLOOKUP(B114,'[1]2021 Team'!$B$2:$G$33,2,FALSE)) -> 0
A115: Ty Long | B115: LAC | C115: P | D115: 0 | E115: 1 | F115: 0 | G115: 0 | H115: 0 | I115: 0 | J115: 0 | K115: =E115/(VLOOKUP(B115,'[1]2021 Team'!$B$2:$G$33,2,FALSE)) -> 0.0014836795
A116: David Montgomery | B116: CHI | C116: RB | D116: 0 | E116: 1 | F116: 0 | G116: 0 | H116: 0 | I116: 100 | J116: 0 | K116: =E116/(VLOOKUP(B116,'[1]2021 Team'!$B$2:$G$33,2,FALSE)) -> 0.0018450185
A117: Cordarrelle Patterson | B117: ATL | C117: RB | D117: 0 | E117: 1 | F117: 0 | G117: 0 | H117: 0 | I117: 0 | J117: 0 | K117: =E117/(VLOOKUP(B117,'[1]2021 Team'!$B$2:$G$33,2,FALSE)) -> 0.0017452007
A118: Brett Rypien | B118: DEN | C118: QB | D118: 0 | E118: 2 | F118: 0 | G118: 0 | H118: 0 | I118: 0 | J118: 0 | K118: =E118/(VLOOKUP(B118,'[1]2021 Team'!$B$2:$G$33,2,FALSE)) -> 0.0036968577
A119: D'Andre Swift | B119: DET | C119: RB | D119: 0 | E119: 1 | F119: 0 | G119: 0 | H119: 0 | I119: 0 | J119: 0 | K119: =E119/(VLOOKUP(B119,'[1]2021 Team'!$B$2:$G$33,2,FALSE)) -> 0.0016863406
A120: Albert Wilson | B120: MIA | C120: WR | D120: 0 | E120: 1 | F120: 0 | G120: 1 | H120: 0 | I120: 0 | J120: 0 | K120: =E120/(VLOOKUP(B120,'[1]2021 Team'!$B$2:$G$33,2,FALSE)) -> 0.0016260163
A121: Brandon Zylstra | B121: CAR | C121: WR | D121: 0 | E121: 1 | F121: 0 | G121: 0 | H121: 0 | I121: 0 | J121: 0 | K121: =E121/(VLOOKUP(B121,'[1]2021 Team'!$B$2:$G$33,2,FALSE)) -> 0.0016694491

Sheet 2025 Rushing
A1: Player | B1: Team | C1: Pos | D1: Att | E1: Yds | F1: TD | G1: TD % | H1: Y/A | I1: Rushing Share
A2: Derrick Henry | B2: BAL | C2: RB | D2: 307 | E2: 1595 | F2: 16 | G2: =F2/D2 -> 0.052117264 | H2: 5.2 | I2: =D2/(VLOOKUP(B2,'2025 Team'!$B$2:$G$33,3,FALSE)) -> 0.60552268
A3: James Cook | B3: BUF | C3: RB | D3: 309 | E3: 1621 | F3: 12 | G3: =F3/D3 -> 0.038834951 | H3: 5.2 | I3: =D3/(VLOOKUP(B3,'2025 Team'!$B$2:$G$33,3,FALSE)) -> 0.56489945
A4: Jonathan Taylor | B4: IND | C4: RB | D4: 323 | E4: 1585 | F4: 18 | G4: =F4/D4 -> 0.055727554 | H4: 4.9 | I4: =D4/(VLOOKUP(B4,'2025 Team'!$B$2:$G$33,3,FALSE)) -> 0.73076923
A5: Saquon Barkley | B5: PHI | C5: RB | D5: 280 | E5: 1140 | F5: 7 | G5: =F5/D5 -> 0.025 | H5: 4.1 | I5: =D5/(VLOOKUP(B5,'2025 Team'!$B$2:$G$33,3,FALSE)) -> 0.58577406
A6: Christian McCaffrey | B6: SFO | C6: RB | D6: 311 | E6: 1202 | F6: 10 | G6: =F6/D6 -> 0.032154341 | H6: 3.9 | I6: =D6/(VLOOKUP(B6,'2025 Team'!$B$2:$G$33,3,FALSE)) -> 0.64656965
A7: Bijan Robinson | B7: ATL | C7: RB | D7: 287 | E7: 1478 | F7: 7 | G7: =F7/D7 -> 0.024390244 | H7: 5.1 | I7: =D7/(VLOOKUP(B7,'2025 Team'!$B$2:$G$33,3,FALSE)) -> 0.60167715
A8: Ashton Jeanty | B8: LVR | C8: RB | D8: 266 | E8: 975 | F8: 5 | G8: =F8/D8 -> 0.018796992 | H8: 3.7 | I8: =D8/(VLOOKUP(B8,'2025 Team'!$B$2:$G$33,3,FALSE)) -> 0.72086721
A9: De'Von Achane | B9: MIA | C9: RB | D9: 238 | E9: 1350 | F9: 8 | G9: =F9/D9 -> 0.033613445 | H9: 5.7 | I9: =D9/(VLOOKUP(B9,'2025 Team'!$B$2:$G$33,3,FALSE)) -> 0.55092593
A10: Breece Hall | B10: NYJ | C10: RB | D10: 243 | E10: 1065 | F10: 4 | G10: =F10/D10 -> 0.016460905 | H10: 4.4 | I10: =D10/(VLOOKUP(B10,'2025 Team'!$B$2:$G$33,3,FALSE)) -> 0.53289474
A11: Josh Jacobs | B11: GNB | C11: RB | D11: 234 | E11: 929 | F11: 13 | G11: =F11/D11 -> 0.055555556 | H11: 4.0 | I11: =D11/(VLOOKUP(B11,'2025 Team'!$B$2:$G$33,3,FALSE)) -> 0.47560976
A12: Travis Etienne | B12: JAX | C12: RB | D12: 260 | E12: 1107 | F12: 7 | G12: =F12/D12 -> 0.026923077 | H12: 4.3 | I12: =D12/(VLOOKUP(B12,'2025 Team'!$B$2:$G$33,3,FALSE)) -> 0.53169734
A13: Kenneth Walker III | B13: SEA | C13: RB | D13: 221 | E13: 1027 | F13: 5 | G13: =F13/D13 -> 0.022624434 | H13: 4.6 | I13: =D13/(VLOOKUP(B13,'2025 Team'!$B$2:$G$33,3,FALSE)) -> 0.43589744
... A343: D'Ernest Johnson | B343: ARI | C343: RB | D343: 1 | E343: 0 | F343: 0 | G343: =F343/D343 -> 0 | H343: 0.0 | I343: =D343/(VLOOKUP(B343,'2025 Team'!$B$2:$G$33,3,FALSE)) -> 0.0027322404
A344: Andre Baccellia | B344: ARI | C344: WR | D344: 0 | E344: 0 | F344: 0 | G344: =F344/D344 -> #DIV/0! | I344: =D344/(VLOOKUP(B344,'2025 Team'!$B$2:$G$33,3,FALSE)) -> 0
A345: Jalen Brooks | B345: ARI | C345: WR | D345: 0 | E345: 0 | F345: 0 | G345: =F345/D345 -> #DIV/0! | I345: =D345/(VLOOKUP(B345,'2025 Team'!$B$2:$G$33,3,FALSE)) -> 0
A346: Pharaoh Brown | B346: ARI | C346: TE | D346: 0 | E346: 0 | F346: 0 | G346: =F346/D346 -> #DIV/0! | I346: =D346/(VLOOKUP(B346,'2025 Team'!$B$2:$G$33,3,FALSE)) -> 0
A347: Josiah Deguara | B347: ARI | C347: TE | D347: 0 | E347: 0 | F347: 0 | G347: =F347/D347 -> #DIV/0! | I347: =D347/(VLOOKUP(B347,'2025 Team'!$B$2:$G$33,3,FALSE)) -> 0
A348: Marvin Harrison Jr. | B348: ARI | C348: WR | D348: 0 | E348: 0 | F348: 0 | G348: =F348/D348 -> #DIV/0! | I348: =D348/(VLOOKUP(B348,'2025 Team'!$B$2:$G$33,3,FALSE)) -> 0
A349: Elijah Higgins | B349: ARI | C349: TE | D349: 0 | E349: 0 | F349: 0 | G349: =F349/D349 -> #DIV/0! | I349: =D349/(VLOOKUP(B349,'2025 Team'!$B$2:$G$33,3,FALSE)) -> 0
A350: Zay Jones | B350: ARI | C350: WR | D350: 0 | E350: 0 | F350: 0 | G350: =F350/D350 -> #DIV/0! | I350: =D350/(VLOOKUP(B350,'2025 Team'!$B$2:$G$33,3,FALSE)) -> 0
A351: Trey McBride | B351: ARI | C351: TE | D351: 0 | E351: 0 | F351: 0 | G351: =F351/D351 -> #DIV/0! | I351: =D351/(VLOOKUP(B351,'2025 Team'!$B$2:$G$33,3,FALSE)) -> 0
A352: Tip Reiman | B352: ARI | C352: TE | D352: 0 | E352: 0 | F352: 0 | G352: =F352/D352 -> #DIV/0! | I352: =D352/(VLOOKUP(B352,'2025 Team'!$B$2:$G$33,3,FALSE)) -> 0
A353: Trent Sherfield | B353: ARI | C353: WR | D353: 0 | E353: 0 | F353: 0 | G353: =F353/D353 -> #DIV/0! | I353: =D353/(VLOOKUP(B353,'2025 Team'!$B$2:$G$33,3,FALSE)) -> 0
A354: Steven Sims | B354: ARI | C354: WR | D354: 0 | E354: 0 | F354: 0 | G354: =F354/D354 -> #DIV/0! | I354: =D354/(VLOOKUP(B354,'2025 Team'!$B$2:$G$33,3,FALSE)) -> 0
A355: Xavier Weaver | B355: ARI | C355: WR | D355: 0 | E355: 0 | F355: 0 | G355: =F355/D355 -> #DIV/0! | I355: =D355/(VLOOKUP(B355,'2025 Team'!$B$2:$G$33,3,FALSE)) -> 0
... A616: Colson Yankoff | B616: WAS | C616: TE | D616: 0 | E616: 0 | F616: 0 | G616: =F616/D616 -> #DIV/0! | I616: =D616/(VLOOKUP(B616,'2025 Team'!$B$2:$G$33,3,FALSE)) -> 0

Sheet 2024 Rushing
A1: Player | B1: Team | C1: Pos | D1: Att | E1: Yds | F1: TD | G1: TD % | H1: Y/A | I1: Rushing Share
A2: Saquon Barkley | B2: PHI | C2: RB | D2: 345 | E2: 2005 | F2: 13 | G2: =F2/D2 -> 0.037681159 | H2: 5.8 | I2: =D2/(VLOOKUP(B2,'2024 Team'!$B$2:$G$33,3,FALSE)) -> 0.55555556
A3: Derrick Henry | B3: BAL | C3: RB | D3: 325 | E3: 1921 | F3: 16 | G3: =F3/D3 -> 0.049230769 | H3: 5.9 | I3: =D3/(VLOOKUP(B3,'2024 Team'!$B$2:$G$33,3,FALSE)) -> 0.5866426
A4: Kyren Williams | B4: LAR | C4: RB | D4: 316 | E4: 1299 | F4: 14 | G4: =F4/D4 -> 0.044303797 | H4: 4.1 | I4: =D4/(VLOOKUP(B4,'2024 Team'!$B$2:$G$33,3,FALSE)) -> 0.70222222
A5: Bijan Robinson | B5: ATL | C5: RB | D5: 304 | E5: 1456 | F5: 14 | G5: =F5/D5 -> 0.046052632 | H5: 4.8 | I5: =D5/(VLOOKUP(B5,'2024 Team'!$B$2:$G$33,3,FALSE)) -> 0.61414141
A6: Jonathan Taylor | B6: IND | C6: RB | D6: 303 | E6: 1431 | F6: 11 | G6: =F6/D6 -> 0.03630363 | H6: 4.7 | I6: =D6/(VLOOKUP(B6,'2024 Team'!$B$2:$G$33,3,FALSE)) -> 0.6108871
A7: Josh Jacobs | B7: GNB | C7: RB | D7: 301 | E7: 1329 | F7: 15 | G7: =F7/D7 -> 0.049833887 | H7: 4.4 | I7: =D7/(VLOOKUP(B7,'2024 Team'!$B$2:$G$33,3,FALSE)) -> 0.57224335
A8: Najee Harris | B8: PIT | C8: RB | D8: 263 | E8: 1043 | F8: 6 | G8: =F8/D8 -> 0.022813688 | H8: 4.0 | I8: =D8/(VLOOKUP(B8,'2024 Team'!$B$2:$G$33,3,FALSE)) -> 0.4934334
A9: Tony Pollard | B9: TEN | C9: RB | D9: 260 | E9: 1079 | F9: 5 | G9: =F9/D9 -> 0.019230769 | H9: 4.2 | I9: =D9/(VLOOKUP(B9,'2024 Team'!$B$2:$G$33,3,FALSE)) -> 0.57777778
A10: Aaron Jones | B10: MIN | C10: RB | D10: 255 | E10: 1138 | F10: 5 | G10: =F10/D10 -> 0.019607843 | H10: 4.5 | I10: =D10/(VLOOKUP(B10,'2024 Team'!$B$2:$G$33,3,FALSE)) -> 0.55798687
A11: D'Andre Swift | B11: CHI | C11: RB | D11: 253 | E11: 959 | F11: 6 | G11: =F11/D11 -> 0.023715415 | H11: 3.8 | I11: =D11/(VLOOKUP(B11,'2024 Team'!$B$2:$G$33,3,FALSE)) -> 0.58700696
A12: Jahmyr Gibbs | B12: DET | C12: RB | D12: 250 | E12: 1412 | F12: 16 | G12: =F12/D12 -> 0.064 | H12: 5.6 | I12: =D12/(VLOOKUP(B12,'2024 Team'!$B$2:$G$33,3,FALSE)) -> 0.46816479
A13: Chuba Hubbard | B13: CAR | C13: RB | D13: 250 | E13: 1195 | F13: 10 | G13: =F13/D13 -> 0.04 | H13: 4.8 | I13: =D13/(VLOOKUP(B13,'2024 Team'!$B$2:$G$33,3,FALSE)) -> 0.6097561
... A267: Diontae Johnson | B267: CAR | C267: WR | D267: 2 | E267: 6 | F267: 0 | G267: =F267/D267 -> 0 | H267: 3.0 | I267: =D267/(VLOOKUP(B267,'2024 Team'!$B$2:$G$33,3,FALSE)) -> 0.0048780488
A268: Diontae Johnson | B268: BAL | C268: WR | D268: 0 | E268: 0 | F268: 0 | G268: =F268/D268 -> #DIV/0! | I268: =D268/(VLOOKUP(B268,'2024 Team'!$B$2:$G$33,3,FALSE)) -> 0
A269: Diontae Johnson | B269: HOU | C269: WR | D269: 0 | E269: 0 | F269: 0 | G269: =F269/D269 -> #DIV/0! | I269: =D269/(VLOOKUP(B269,'2024 Team'!$B$2:$G$33,3,FALSE)) -> 0
A270: Kameron Johnson | B270: TAM | C270: WR | D270: 2 | E270: 11 | F270: 0 | G270: =F270/D270 -> 0 | H270: 5.5 | I270: =D270/(VLOOKUP(B270,'2024 Team'!$B$2:$G$33,3,FALSE)) -> 0.0041407867
A271: Cooper Kupp | B271: LAR | C271: WR | D271: 2 | E271: 10 | F271: 0 | G271: =F271/D271 -> 0 | H271: 5.0 | I271: =D271/(VLOOKUP(B271,'2024 Team'!$B$2:$G$33,3,FALSE)) -> 0.0044444444
A272: Tyreik McAllister | B272: LVR | C272: WR | D272: 2 | E272: 11 | F272: 0 | G272: =F272/D272 -> 0 | H272: 5.5 | I272: =D272/(VLOOKUP(B272,'2024 Team'!$B$2:$G$33,3,FALSE)) -> 0.0052631579
A273: Terry McLaurin | B273: WAS | C273: WR | D273: 2 | E273: 2 | F273: 0 | G273: =F273/D273 -> 0 | H273: 1.0 | I273: =D273/(VLOOKUP(B273,'2024 Team'!$B$2:$G$33,3,FALSE)) -> 0.0038022814
A274: Jakobi Meyers | B274: LVR | C274: WR | D274: 2 | E274: 23 | F274: 0 | G274: =F274/D274 -> 0 | H274: 11.5 | I274: =D274/(VLOOKUP(B274,'2024 Team'!$B$2:$G$33,3,FALSE)) -> 0.0052631579
A275: Jonathan Mingo | B275: CAR | C275: WR | D275: 2 | E275: 5 | F275: 0 | G275: =F275/D275 -> 0 | H275: 2.5 | I275: =D275/(VLOOKUP(B275,'2024 Team'!$B$2:$G$33,3,FALSE)) -> 0.0048780488
A276: Jonathan Mingo | B276: DAL | C276: WR | D276: 0 | E276: 0 | F276: 0 | G276: =F276/D276 -> #DIV/0! | I276: =D276/(VLOOKUP(B276,'2024 Team'!$B$2:$G$33,3,FALSE)) -> 0
A277: George Pickens | B277: PIT | C277: WR | D277: 2 | E277: -6 | F277: 0 | G277: =F277/D277 -> 0 | H277: -3.0 | I277: =D277/(VLOOKUP(B277,'2024 Team'!$B$2:$G$33,3,FALSE)) -> 0.0037523452
A278: Kalif Raymond | B278: DET | C278: WR | D278: 2 | E278: 0 | F278: 0 | G278: =F278/D278 -> 0 | H278: 0.0 | I278: =D278/(VLOOKUP(B278,'2024 Team'!$B$2:$G$33,3,FALSE)) -> 0.0037453184
A279: Khalil Shakir | B279: BUF | C279: WR | D279: 2 | E279: 4 | F279: 0 | G279: =F279/D279 -> 0 | H279: 2.0 | I279: =D279/(VLOOKUP(B279,'2024 Team'!$B$2:$G$33,3,FALSE)) -> 0.0040733198
A280: Darius Slayton | B280: NYG | C280: WR | D280: 2 | E280: 17 | F280: 0 | G280: =F280/D280 -> 0 | H280: 8.5 | I280: =D280/(VLOOKUP(B280,'2024 Team'!$B$2:$G$33,3,FALSE)) -> 0.0047169811
A281: Ainias Smith | B281: PHI | C281: WR | D281: 2 | E281: 6 | F281: 0 | G281: =F281/D281 -> 0 | H281: 3.0 | I281: =D281/(VLOOKUP(B281,'2024 Team'!$B$2:$G$33,3,FALSE)) -> 0.0032206119
A282: Jonnu Smith | B282: MIA | C282: TE | D282: 2 | E282: -1 | F282: 0 | G282: =F282/D282 -> 0 | H282: -0.5 | I282: =D282/(VLOOKUP(B282,'2024 Team'!$B$2:$G$33,3,FALSE)) -> 0.0044642857
A283: Amon-Ra St. Brown | B283: DET | C283: WR | D283: 2 | E283: 6 | F283: 0 | G283: =F283/D283 -> 0 | H283: 3.0 | I283: =D283/(VLOOKUP(B283,'2024 Team'!$B$2:$G$33,3,FALSE)) -> 0.0037453184
A284: Deven Thompkins | B284: CAR | C284: WR | D284: 2 | E284: 7 | F284: 0 | G284: =F284/D284 -> 0 | H284: 3.5 | I284: =D284/(VLOOKUP(B284,'2024 Team'!$B$2:$G$33,3,FALSE)) -> 0.0048780488
A285: Kadarius Toney | B285: CLE | C285: WR | D285: 2 | E285: -4 | F285: 0 | G285: =F285/D285 -> 0 | H285: -2.0 | I285: =D285/(VLOOKUP(B285,'2024 Team'!$B$2:$G$33,3,FALSE)) -> 0.0051150895
A286: Ke'Shawn Vaughn | B286: SFO | C286: RB | D286: 2 | E286: 4 | F286: 0 | G286: =F286/D286 -> 0 | H286: 2.0 | I286: =D286/(VLOOKUP(B286,'2024 Team'!$B$2:$G$33,3,FALSE)) -> 0.0043763676
A287: Jordan Whittington | B287: LAR | C287: WR | D287: 2 | E287: 12 | F287: 0 | G287: =F287/D287 -> 0 | H287: 6.0 | I287: =D287/(VLOOKUP(B287,'2024 Team'!$B$2:$G$33,3,FALSE)) -> 0.0044444444
A288: Garrett Wilson | B288: NYJ | C288: WR | D288: 2 | E288: 5 | F288: 0 | G288: =F288/D288 -> 0 | H288: 2.5 | I288: =D288/(VLOOKUP(B288,'2024 Team'!$B$2:$G$33,3,FALSE)) -> 0.0055096419
... A338: Cedric Tillman | B338: CLE | C338: WR | D338: 1 | E338: -5 | F338: 0 | G338: =F338/D338 -> 0 | H338: -5.0 | I338: =D338/(VLOOKUP(B338,'2024 Team'!$B$2:$G$33,3,FALSE)) -> 0.0025575448
A339: Marquez Valdes-Scantling | B339: BUF | C339: WR | D339: 0 | E339: 0 | F339: 0 | G339: =F339/D339 -> #DIV/0! | I339: =D339/(VLOOKUP(B339,'2024 Team'!$B$2:$G$33,3,FALSE)) -> 0
A340: Marquez Valdes-Scantling | B340: NOR | C340: WR | D340: 1 | E340: 4 | F340: 0 | G340: =F340/D340 -> 0 | H340: 4.0 | I340: =D340/(VLOOKUP(B340,'2024 Team'!$B$2:$G$33,3,FALSE)) -> 0.0022522523
A341: Michael Wilson | B341: ARI | C341: WR | D341: 1 | E341: 7 | F341: 0 | G341: =F341/D341 -> 0 | H341: 7.0 | I341: =D341/(VLOOKUP(B341,'2024 Team'!$B$2:$G$33,3,FALSE)) -> 0.0021598272
A342: Olamide Zaccheaus | B342: WAS | C342: WR | D342: 1 | E342: 8 | F342: 0 | G342: =F342/D342 -> 0 | H342: 8.0 | I342: =D342/(VLOOKUP(B342,'2024 Team'!$B$2:$G$33,3,FALSE)) -> 0.0019011407
...

Sheet 2023 Rushing
A1: Player | B1: Team | C1: Pos | D1: Att | E1: Yds | F1: TD | G1: TD % | H1: Y/A | I1: Rushing Share
A2: Derrick Henry | B2: TEN | C2: RB | D2: 280 | E2: 1167 | F2: 12 | G2: =F2/D2 -> 0.042857143 | H2: 4.2 | I2: =D2/(VLOOKUP(B2,'2023 Team'!$B$2:$G$33,3,FALSE)) -> 0.63063063
A3: Christian McCaffrey | B3: SFO | C3: RB | D3: 272 | E3: 1459 | F3: 14 | G3: =F3/D3 -> 0.051470588 | H3: 5.4 | I3: =D3/(VLOOKUP(B3,'2023 Team'!$B$2:$G$33,3,FALSE)) -> 0.54509018
A4: Rachaad White | B4: TAM | C4: RB | D4: 272 | E4: 990 | F4: 6 | G4: =F4/D4 -> 0.022058824 | H4: 3.6 | I4: =D4/(VLOOKUP(B4,'2023 Team'!$B$2:$G$33,3,FALSE)) -> 0.61958998
A5: Travis Etienne | B5: JAX | C5: RB | D5: 267 | E5: 1008 | F5: 11 | G5: =F5/D5 -> 0.041198502 | H5: 3.8 | I5: =D5/(VLOOKUP(B5,'2023 Team'!$B$2:$G$33,3,FALSE)) -> 0.58940397
A6: Joe Mixon | B6: CIN | C6: RB | D6: 257 | E6: 1034 | F6: 9 | G6: =F6/D6 -> 0.035019455 | H6: 4.0 | I6: =D6/(VLOOKUP(B6,'2023 Team'!$B$2:$G$33,3,FALSE)) -> 0.67101828
A7: Najee Harris | B7: PIT | C7: RB | D7: 255 | E7: 1035 | F7: 8 | G7: =F7/D7 -> 0.031372549 | H7: 4.1 | I7: =D7/(VLOOKUP(B7,'2023 Team'!$B$2:$G$33,3,FALSE)) -> 0.52361396
A8: Tony Pollard | B8: DAL | C8: RB | D8: 252 | E8: 1005 | F8: 6 | G8: =F8/D8 -> 0.023809524 | H8: 4.0 | I8: =D8/(VLOOKUP(B8,'2023 Team'!$B$2:$G$33,3,FALSE)) -> 0.53846154
A9: Saquon Barkley | B9: NYG | C9: RB | D9: 247 | E9: 962 | F9: 6 | G9: =F9/D9 -> 0.024291498 | H9: 3.9 | I9: =D9/(VLOOKUP(B9,'2023 Team'!$B$2:$G$33,3,FALSE)) -> 0.54405286
A10: Chuba Hubbard | B10: CAR | C10: RB | D10: 238 | E10: 902 | F10: 5 | G10: =F10/D10 -> 0.021008403 | H10: 3.8 | I10: =D10/(VLOOKUP(B10,'2023 Team'!$B$2:$G$33,3,FALSE)) -> 0.53483146
A11: James Cook | B11: BUF | C11: RB | D11: 237 | E11: 1122 | F11: 2 | G11: =F11/D11 -> 0.0084388186 | H11: 4.7 | I11: =D11/(VLOOKUP(B11,'2023 Team'!$B$2:$G$33,3,FALSE)) -> 0.46289062
A12: Josh Jacobs | B12: LVR | C12: RB | D12: 233 | E12: 805 | F12: 6 | G12: =F12/D12 -> 0.025751073 | H12: 3.5 | I12: =D12/(VLOOKUP(B12,'2023 Team'!$B$2:$G$33,3,FALSE)) -> 0.56416465
A13: D'Andre Swift | B13: PHI | C13: RB | D13: 229 | E13: 1049 | F13: 5 | G13: =F13/D13 -> 0.021834061 | H13: 4.6 | I13: =D13/(VLOOKUP(B13,'2023 Team'!$B$2:$G$33,3,FALSE)) -> 0.44901961
... A312: C.J. Ham | B312: MIN | C312: FB | D312: 1 | E312: 7 | F312: 0 | G312: =F312/D312 -> 0 | H312: 7.0 | I312: =D312/(VLOOKUP(B312,'2023 Team'!$B$2:$G$33,3,FALSE)) -> 0.0025445293
A313: Mecole Hardman | B313: NYJ | C313: WR | D313: 0 | E313: 0 | F313: 0 | G313: =F313/D313 -> #DIV/0! | I313: =D313/(VLOOKUP(B313,'2023 Team'!$B$2:$G$33,3,FALSE)) -> 0
A314: Mecole Hardman | B314: KAN | C314: WR | D314: 1 | E314: 3 | F314: 0 | G314: =F314/D314 -> 0 | H314: 3.0 | I314: =D314/(VLOOKUP(B314,'2023 Team'!$B$2:$G$33,3,FALSE)) -> 0.0023980815
A315: Johnny Hekker | B315: CAR | C315: P | D315: 1 | E315: -11 | F315: 0 | G315: =F315/D315 -> 0 | H315: -11.0 | I315: =D315/(VLOOKUP(B315,'2023 Team'!$B$2:$G$33,3,FALSE)) -> 0.002247191
A316: Peyton Hendershot | B316: DAL | C316: TE | D316: 1 | E316: 0 | F316: 0 | G316: =F316/D316 -> 0 | H316: 0.0 | I316: =D316/(VLOOKUP(B316,'2023 Team'!$B$2:$G$33,3,FALSE)) -> 0.0021367521
A317: Connor Heyward | B317: PIT | C317: TE | D317: 1 | E317: 0 | F317: 0 | G317: =F317/D317 -> 0 | H317: 0.0 | I317: =D317/(VLOOKUP(B317,'2023 Team'!$B$2:$G$33,3,FALSE)) -> 0.0020533881
A318: KhaDarel Hodge | B318: ATL | C318: WR | D318: 1 | E318: 0 | F318: 0 | G318: =F318/D318 -> 0 | H318: 0.0 | I318: =D318/(VLOOKUP(B318,'2023 Team'!$B$2:$G$33,3,FALSE)) -> 0.0019157088
A319: Amani Hooker | B319: TEN | C319: DB | D319: 1 | E319: 2 | F319: 0 | G319: =F319/D319 -> 0 | H319: 2.0 | I319: =D319/(VLOOKUP(B319,'2023 Team'!$B$2:$G$33,3,FALSE)) -> 0.0022522523
A320: Evan Hull | B320: IND | C320: RB | D320: 1 | E320: 1 | F320: 0 | G320: =F320/D320 -> 0 | H320: 1.0 | I320: =D320/(VLOOKUP(B320,'2023 Team'!$B$2:$G$33,3,FALSE)) -> 0.0020876827
A321: Rakim Jarrett | B321: TAM | C321: WR | D321: 1 | E321: 0 | F321: 0 | G321: =F321/D321 -> 0 | H321: 0.0 | I321: =D321/(VLOOKUP(B321,'2023 Team'!$B$2:$G$33,3,FALSE)) -> 0.0022779043
A322: Justin Jefferson | B322: MIN | C322: WR | D322: 1 | E322: -12 | F322: 0 | G322: =F322/D322 -> 0 | H322: -12.0 | I322: =D322/(VLOOKUP(B322,'2023 Team'!$B$2:$G$33,3,FALSE)) -> 0.0025445293
A323: Van Jefferson | B323: LAR | C323: WR | D323: 1 | E323: 4 | F323: 0 | G323: =F323/D323 -> 0 | H323: 4.0 | I323: =D323/(VLOOKUP(B323,'2023 Team'!$B$2:$G$33,3,FALSE)) -> 0.0020964361
A324: Van Jefferson | B324: ATL | C324: WR | D324: 0 | E324: 0 | F324: 0 | G324: =F324/D324 -> #DIV/0! | I324: =D324/(VLOOKUP(B324,'2023 Team'!$B$2:$G$33,3,FALSE)) -> 0
A325: Cameron Johnston | B325: HOU | C325: P | D325: 1 | E325: -23 | F325: 0 | G325: =F325/D325 -> 0 | H325: -23.0 | I325: =D325/(VLOOKUP(B325,'2023 Team'!$B$2:$G$33,3,FALSE)) -> 0.0022522523
A326: Christian Kirk | B326: JAX | C326: WR | D326: 1 | E326: 6 | F326: 0 | G326: =F326/D326 -> 0 | H326: 6.0 | I326: =D326/(VLOOKUP(B326,'2023 Team'!$B$2:$G$33,3,FALSE)) -> 0.0022075055
A327: George Kittle | B327: SFO | C327: TE | D327: 1 | E327: 2 | F327: 0 | G327: =F327/D327 -> 0 | H327: 2.0 | I327: =D327/(VLOOKUP(B327,'2023 Team'!$B$2:$G$33,3,FALSE)) -> 0.002004008
A328: Cooper Kupp | B328: LAR | C328: WR | D328: 1 | E328: -3 | F328: 0 | G328: =F328/D328 -> 0 | H328: -3.0 | I328: =D328/(VLOOKUP(B328,'2023 Team'!$B$2:$G$33,3,FALSE)) -> 0.0020964361
A329: Sam LaPorta | B329: DET | C329: TE | D329: 1 | E329: 4 | F329: 0 | G329: =F329/D329 -> 0 | H329: 4.0 | I329: =D329/(VLOOKUP(B329,'2023 Team'!$B$2:$G$33,3,FALSE)) -> 0.002
A330: John Metchie | B330: HOU | C330: WR | D330: 1 | E330: 4 | F330: 0 | G330: =F330/D330 -> 0 | H330: 4.0 | I330: =D330/(VLOOKUP(B330,'2023 Team'!$B$2:$G$33,3,FALSE)) -> 0.0022522523
A331: Nick Niemann | B331: LAC | C331: LB | D331: 1 | E331: 0 | F331: 0 | G331: =F331/D331 -> 0 | H331: 0.0 | I331: =D331/(VLOOKUP(B331,'2023 Team'!$B$2:$G$33,3,FALSE)) -> 0.0023201856
A332: Keisean Nixon | B332: GNB | C332: CB | D332: 1 | E332: 11 | F332: 0 | G332: =F332/D332 -> 0 | H332: 11.0 | I332: =D332/(VLOOKUP(B332,'2023 Team'!$B$2:$G$33,3,FALSE)) -> 0.0022675737
A333: Josh Palmer | B333: LAC | C333: WR | D333: 1 | E333: 6 | F333: 0 | G333: =F333/D333 -> 0 | H333: 6.0 | I333: =D333/(VLOOKUP(B333,'2023 Team'!$B$2:$G$33,3,FALSE)) -> 0.0023201856
A334: Kyle Pitts | B334: ATL | C334: TE | D334: 1 | E334: -4 | F334: 0 | G334: =F334/D334 -> 0 | H334: -4.0 | I334: =D334/(VLOOKUP(B334,'2023 Team'!$B$2:$G$33,3,FALSE)) -> 0.0019157088
A335: Jalen Reagor | B335: NWE | C335: WR | D335: 1 | E335: 17 | F335: 0 | G335: =F335/D335 -> 0 | H335: 17.0 | I335: =D335/(VLOOKUP(B335,'2023 Team'!$B$2:$G$33,3,FALSE)) -> 0.0024096386
A336: Rashee Rice | B336: KAN | C336: WR | D336: 1 | E336: -3 | F336: 0 | G336: =F336/D336 -> 0 | H336: -3.0 | I336: =D336/(VLOOKUP(B336,'2023 Team'!$B$2:$G$33,3,FALSE)) -> 0.0023980815
... A356: Ty Zentner | B356: TEN | C356: P | D356: 1 | E356: 0 | F356: 0 | G356: =F356/D356 -> 0 | H356: 0.0 | I356: =D356/(VLOOKUP(B356,'2023 Team'!$B$2:$G$33,3,FALSE)) -> 0.0022522523
A357: Davante Adams | B357: LVR | C357: WR | D357: 0 | E357: 0 | F357: 0 | G357: =F357/D357 -> #DIV/0! | I357: =D357/(VLOOKUP(B357,'2023 Team'!$B$2:$G$33,3,FALSE)) -> 0
...

Sheet 2022 Rushing
A1: Player | B1: Team | C1: Pos | D1: Att | E1: Yds | F1: TD | G1: TD % | H1: Y/A | I1: Rushing Share
A2: Derrick Henry | B2: TEN | C2: RB | D2: 349 | E2: 1538 | F2: 13 | G2: =F2/D2 -> 0.037249284 | H2: 4.4 | I2: =D2/(VLOOKUP(B2,'[1]2022 Team'!$B$2:$G$33,3,FALSE)) -> 0.71663244
A3: Josh Jacobs | B3: LVR | C3: RB | D3: 340 | E3: 1653 | F3: 12 | G3: =F3/D3 -> 0.035294118 | H3: 4.9 | I3: =D3/(VLOOKUP(B3,'[1]2022 Team'!$B$2:$G$33,3,FALSE)) -> 0.79439252
A4: Nick Chubb | B4: CLE | C4: RB | D4: 302 | E4: 1525 | F4: 12 | G4: =F4/D4 -> 0.039735099 | H4: 5 | I4: =D4/(VLOOKUP(B4,'[1]2022 Team'!$B$2:$G$33,3,FALSE)) -> 0.56766917
A5: Saquon Barkley | B5: NYG | C5: RB | D5: 295 | E5: 1312 | F5: 10 | G5: =F5/D5 -> 0.033898305 | H5: 4.4 | I5: =D5/(VLOOKUP(B5,'[1]2022 Team'!$B$2:$G$33,3,FALSE)) -> 0.56730769
A6: Najee Harris | B6: PIT | C6: RB | D6: 272 | E6: 1034 | F6: 7 | G6: =F6/D6 -> 0.025735294 | H6: 3.8 | I6: =D6/(VLOOKUP(B6,'[1]2022 Team'!$B$2:$G$33,3,FALSE)) -> 0.544
A7: Dalvin Cook | B7: MIN | C7: RB | D7: 264 | E7: 1173 | F7: 8 | G7: =F7/D7 -> 0.03030303 | H7: 4.4 | I7: =D7/(VLOOKUP(B7,'[1]2022 Team'!$B$2:$G$33,3,FALSE)) -> 0.65346535
A8: Jamaal Williams | B8: DET | C8: RB | D8: 262 | E8: 1066 | F8: 17 | G8: =F8/D8 -> 0.064885496 | H8: 4.1 | I8: =D8/(VLOOKUP(B8,'[1]2022 Team'!$B$2:$G$33,3,FALSE)) -> 0.54583333
A9: Miles Sanders | B9: PHI | C9: RB | D9: 259 | E9: 1269 | F9: 11 | G9: =F9/D9 -> 0.042471042 | H9: 4.9 | I9: =D9/(VLOOKUP(B9,'[1]2022 Team'!$B$2:$G$33,3,FALSE)) -> 0.47610294
A10: Christian McCaffrey | B10: CAR | C10: RB | D10: 85 | E10: 393 | F10: 2 | G10: =F10/D10 -> 0.023529412 | H10: 4.6 | I10: =D10/(VLOOKUP(B10,'[1]2022 Team'!$B$2:$G$33,3,FALSE)) -> 0.17598344
A11: Christian McCaffrey | B11: SFO | C11: RB | D11: 159 | E11: 746 | F11: 6 | G11: =F11/D11 -> 0.037735849 | H11: 4.7 | I11: =D11/(VLOOKUP(B11,'[1]2022 Team'!$B$2:$G$33,3,FALSE)) -> 0.31547619
A12: Ezekiel Elliott | B12: DAL | C12: RB | D12: 231 | E12: 876 | F12: 12 | G12: =F12/D12 -> 0.051948052 | H12: 3.8 | I12: =D12/(VLOOKUP(B12,'[1]2022 Team'!$B$2:$G$33,3,FALSE)) -> 0.43502825
A13: Kenneth Walker III | B13: SEA | C13: RB | D13: 228 | E13: 1050 | F13: 9 | G13: =F13/D13 -> 0.039473684 | H13: 4.6 | I13: =D13/(VLOOKUP(B13,'[1]2022 Team'!$B$2:$G$33,3,FALSE)) -> 0.53647059
... A324: Wan'Dale Robinson | B324: NYG | C324: WR | D324: 2 | E324: -1 | F324: 0 | G324: =F324/D324 -> 0 | H324: -0.5 | I324: =D324/(VLOOKUP(B324,'[1]2022 Team'!$B$2:$G$33,3,FALSE)) -> 0.0038461538
A325: Amari Rodgers | B325: GNB | C325: WR | D325: 0 | E325: 0 | F325: 0 | G325: =F325/D325 -> #DIV/0! | I325: =D325/(VLOOKUP(B325,'[1]2022 Team'!$B$2:$G$33,3,FALSE)) -> 0
A326: Amari Rodgers | B326: HOU | C326: WR | D326: 2 | E326: 7 | F326: 0 | G326: =F326/D326 -> 0 | H326: 3.5 | I326: =D326/(VLOOKUP(B326,'[1]2022 Team'!$B$2:$G$33,3,FALSE)) -> 0.0050251256
A327: Armani Rogers | B327: WAS | C327: TE | D327: 2 | E327: 26 | F327: 0 | G327: =F327/D327 -> 0 | H327: 13 | I327: =D327/(VLOOKUP(B327,'[1]2022 Team'!$B$2:$G$33,3,FALSE)) -> 0.0037174721
A328: Trey Sermon | B328: PHI | C328: RB | D328: 2 | E328: 19 | F328: 0 | G328: =F328/D328 -> 0 | H328: 9.5 | I328: =D328/(VLOOKUP(B328,'[1]2022 Team'!$B$2:$G$33,3,FALSE)) -> 0.0036764706
A329: Durham Smythe | B329: MIA | C329: TE | D329: 2 | E329: 1 | F329: 1 | G329: =F329/D329 -> 0.5 | H329: 0.5 | I329: =D329/(VLOOKUP(B329,'[1]2022 Team'!$B$2:$G$33,3,FALSE)) -> 0.0051282051
A330: Deven Thompkins | B330: TAM | C330: WR | D330: 2 | E330: 26 | F330: 0 | G330: =F330/D330 -> 0 | H330: 13 | I330: =D330/(VLOOKUP(B330,'[1]2022 Team'!$B$2:$G$33,3,FALSE)) -> 0.0051813472
A331: Damien Williams | B331: ATL | C331: RB | D331: 2 | E331: 2 | F331: 0 | G331: =F331/D331 -> 0 | H331: 1 | I331: =D331/(VLOOKUP(B331,'[1]2022 Team'!$B$2:$G$33,3,FALSE)) -> 0.0035778175
A332: Olamide Zaccheaus | B332: ATL | C332: WR | D332: 2 | E332: 7 | F332: 0 | G332: =F332/D332 -> 0 | H332: 3.5 | I332: =D332/(VLOOKUP(B332,'[1]2022 Team'!$B$2:$G$33,3,FALSE)) -> 0.0035778175
